<?xml version="1.0" ?>
<mujoco model="meca500">
  <compiler angle="radian"/>
  <actuator>
    <motor ctrllimited="true" ctrlrange="-16.6 16.6" joint="meca_axis_1_joint" name="torq_j1"/>
    <motor ctrllimited="true" ctrlrange="-16.6 16.6" joint="meca_axis_2_joint" name="torq_j2"/>
    <motor ctrllimited="true" ctrlrange="-16.6 16.6" joint="meca_axis_3_joint" name="torq_j3"/>
    <motor ctrllimited="true" ctrlrange="-2.5 2.5" joint="meca_axis_4_joint" name="torq_j4"/>
    <motor ctrllimited="true" ctrlrange="-2.5 2.5" joint="meca_axis_5_joint" name="torq_j5"/>
    <motor ctrllimited="true" ctrlrange="-1.5 1.5" joint="meca_axis_6_joint" name="torq_j6"/>
  </actuator>
  <asset>
    <mesh name="base" file="meshes/meca_500_r3_base.stl"/>
    <mesh name="base_collision" file="meshes/meca_500_r3_base_collision.stl"/>
    <mesh name="j1" file="meshes/meca_500_r3_j1.stl"/>
    <mesh name="j1_collision" file="meshes/meca_500_r3_j1_collision.stl"/>
    <mesh name="j2" file="meshes/meca_500_r3_j2.stl"/>
    <mesh name="j2_collision" file="meshes/meca_500_r3_j2_collision.stl"/>
    <mesh name="j3" file="meshes/meca_500_r3_j3.stl"/>
    <mesh name="j3_collision" file="meshes/meca_500_r3_j3_collision.stl"/>
    <mesh name="j4" file="meshes/meca_500_r3_j4.stl"/>
    <mesh name="j4_collision" file="meshes/meca_500_r3_j4_collision.stl"/>
    <mesh name="j5" file="meshes/meca_500_r3_j5.stl"/>
    <mesh name="j5_collision" file="meshes/meca_500_r3_j5_collision.stl"/>
    <mesh name="j6" file="meshes/meca_500_r3_j6.stl"/>
    <mesh name="j6_collision" file="meshes/meca_500_r3_j6_collision.stl"/>
  </asset>
  <worldbody>
    <body name="base" pos="0 0 0">
      <!-- robot view -->
      <camera mode="fixed" name="robotview" pos="1.0 0 0.4" quat="0.653 0.271 0.271 0.653"/>
      <inertial diaginertia="0 0 0" mass="0" pos="0 0 0"/>
      <!-- mount attached here -->
      <body name="fixed_base_link" pos="0 0 0">
        <geom type="mesh" contype="0" conaffinity="0" group="1" density="0" mesh="base"/>
        <geom type="mesh" rgba="1 0.3 0.3 1" mesh="base_collision"/>
        <body name="meca_axis_1_link" pos="0.012498 0 0.091" quat="1 0 0 0">
          <inertial pos="0 0 0" quat="1 0 0 0" mass="0.1" diaginertia="0.03 0.03 0.03"/>
          <joint name="meca_axis_1_joint" pos="0 0 0" axis="0 0 1" range="-3.05433 3.05433" damping="0.1"/>
          <geom type="mesh" contype="0" conaffinity="0" group="1" name="j1_visual" mesh="j1"/>
          <geom type="mesh" rgba="1 0.3 0.3 1" mesh="j1_collision" name="j1_collision"/>
          <body name="meca_axis_2_link" pos="0 0 0.044" quat="1 0 0 0">
            <inertial pos="0 0 0" quat="1 0 0 0" mass="0.1" diaginertia="0.03 0.03 0.03"/>
            <joint name="meca_axis_2_joint" pos="0 0 0" axis="0 1 0" range="-1.22173048 1.5708" damping="0.1"/>
            <geom type="mesh" contype="0" conaffinity="0" group="1" name="j2_visual" mesh="j2"/>
            <geom type="mesh" rgba="1 0.3 0.3 1" mesh="j2_collision" name="j2_collision"/>
            <body name="meca_axis_3_link" pos="0 0 0.135" quat="1 0 0 0">
              <inertial pos="0 0 0" quat="1 0 0 0" mass="0.1" diaginertia="0.03 0.03 0.03"/>
              <joint name="meca_axis_3_joint" pos="0 0 0" axis="0 1 0" range="-2.35619 1.22173" damping="0.1"/>
              <geom type="mesh" contype="0" conaffinity="0" group="1" name="j3_visual" mesh="j3"/>
              <geom type="mesh" rgba="1 0.3 0.3 1" mesh="j3_collision" name="j3_collision"/>
              <body name="meca_axis_4_link" pos="0 0 0.038" quat="1 0 0 0">
                <inertial pos="0 0 0" quat="1 0 0 0" mass="0.1" diaginertia="0.03 0.03 0.03"/>
                <joint name="meca_axis_4_joint" pos="0 0 0" axis="1 0 0" range="-2.96706 2.96706" damping="0.1"/>
                <geom type="mesh" contype="0" conaffinity="0" group="1" name="j4_visual" mesh="j4"/>
                <geom type="mesh" rgba="1 0.3 0.3 1" mesh="j4_collision" name="j4_collision"/>
                <body name="meca_axis_5_link" pos="0.12 0 0" quat="1 0 0 0">
                  <inertial pos="0 0 0" quat="1 0 0 0" mass="0.1" diaginertia="0.03 0.03 0.03"/>
                  <joint name="meca_axis_5_joint" pos="0 0 0" axis="0 1 0" range="-2.00713 2.00713" damping="0.1"/>
                  <geom type="mesh" contype="0" conaffinity="0" group="1" name="j5_visual" mesh="j5"/>
                  <geom type="mesh" rgba="1 0.3 0.3 1" mesh="j5_collision" name="j5_collision"/>
                  <body name="meca_axis_6_link" pos="0.07 0 0" quat="1 0 0 0">
                    <inertial pos="0 0 0" quat="1 0 0 0" mass="0.1" diaginertia="0.03 0.03 0.03"/>
                    <joint name="meca_axis_6_joint" pos="0 0 0" axis="1 0 0" range="-3.14159 3.14159" damping="0.1"/>
                    <geom type="mesh" contype="0" conaffinity="0" group="1" name="j6_visual" mesh="j6"/>
                    <geom type="mesh" rgba="1 0.3 0.3 1" mesh="j6_collision" name="j6_collision"/>
                  </body>
                </body>
              </body>
            </body>
          </body>
        </body>
      </body>
    </body>
  </worldbody>
</mujoco>
