<mujoco model="meca_500_r3">
  <compiler angle="radian" meshdir="meshes/"/>
  <actuator>
    <motor ctrllimited="true" ctrlrange="-16.6 16.6" joint="meca_axis_1_joint" name="torq_j1"/>
    <motor ctrllimited="true" ctrlrange="-16.6 16.6" joint="meca_axis_2_joint" name="torq_j2"/>
    <motor ctrllimited="true" ctrlrange="-16.6 16.6" joint="meca_axis_3_joint" name="torq_j3"/>
    <motor ctrllimited="true" ctrlrange="-2.5 2.5" joint="meca_axis_4_joint" name="torq_j4"/>
    <motor ctrllimited="true" ctrlrange="-2.5 2.5" joint="meca_axis_5_joint" name="torq_j5"/>
    <motor ctrllimited="true" ctrlrange="-1.5 1.5" joint="meca_axis_6_joint" name="torq_j6"/>
  </actuator>
  <asset>
    <mesh name="meca_500_r3_base" file="meca_500_r3_base.stl"/>
    <!-- <mesh name="meca_500_r3_base_collision" file="meca_500_r3_base_collision.stl"/> -->
    <mesh name="meca_500_r3_j1" file="meca_500_r3_j1.stl"/>
    <!-- <mesh name="meca_500_r3_j1_collision" file="meca_500_r3_j1_collision.stl"/> -->
    <mesh name="meca_500_r3_j2" file="meca_500_r3_j2.stl"/>
    <!-- <mesh name="meca_500_r3_j2_collision" file="meca_500_r3_j2_collision.stl"/> -->
    <mesh name="meca_500_r3_j3" file="meca_500_r3_j3.stl"/>
    <!-- <mesh name="meca_500_r3_j3_collision" file="meca_500_r3_j3_collision.stl"/> -->
    <mesh name="meca_500_r3_j4" file="meca_500_r3_j4.stl"/>
    <!-- <mesh name="meca_500_r3_j4_collision" file="meca_500_r3_j4_collision.stl"/> -->
    <mesh name="meca_500_r3_j5" file="meca_500_r3_j5.stl"/>
    <!-- <mesh name="meca_500_r3_j5_collision" file="meca_500_r3_j5_collision.stl"/> -->
    <mesh name="meca_500_r3_j6" file="meca_500_r3_j6.stl"/>
    <!-- <mesh name="meca_500_r3_j6_collision" file="meca_500_r3_j6_collision.stl"/> -->
  </asset>
  <worldbody>
    <geom type="mesh" contype="0" conaffinity="0" group="1" density="0" mesh="meca_500_r3_base"/>
    <geom type="mesh" mesh="meca_500_r3_base_collision"/>
    <body name="meca_axis_1_link" pos="0.012498 0 0.091">
      <joint name="meca_axis_1_joint" pos="0 0 0" axis="0 0 1" range="-3.05433 3.05433" actuatorfrcrange="-10 10"/>
      <geom type="mesh" contype="0" conaffinity="0" group="1" density="0" mesh="meca_500_r3_j1"/>
      <geom type="mesh" mesh="meca_500_r3_j1_collision"/>
      <body name="meca_axis_2_link" pos="0 0 0.044">
        <joint name="meca_axis_2_joint" pos="0 0 0" axis="0 1 0" range="-1.22173 1.5708" actuatorfrcrange="-10 10"/>
        <geom type="mesh" contype="0" conaffinity="0" group="1" density="0" mesh="meca_500_r3_j2"/>
        <geom type="mesh" mesh="meca_500_r3_j2_collision"/>
        <body name="meca_axis_3_link" pos="0 0 0.135">
          <joint name="meca_axis_3_joint" pos="0 0 0" axis="0 1 0" range="-2.35619 1.22173" actuatorfrcrange="-10 10"/>
          <geom type="mesh" contype="0" conaffinity="0" group="1" density="0" mesh="meca_500_r3_j3"/>
          <geom type="mesh" mesh="meca_500_r3_j3_collision"/>
          <body name="meca_axis_4_link" pos="0 0 0.038">
            <joint name="meca_axis_4_joint" pos="0 0 0" axis="1 0 0" range="-2.96706 2.96706" actuatorfrcrange="-10 10"/>
            <geom type="mesh" contype="0" conaffinity="0" group="1" density="0" mesh="meca_500_r3_j4"/>
            <geom type="mesh" mesh="meca_500_r3_j4_collision"/>
            <body name="meca_axis_5_link" pos="0.12 0 0">
              <joint name="meca_axis_5_joint" pos="0 0 0" axis="0 1 0" range="-2.00713 2.00713" actuatorfrcrange="-10 10"/>
              <geom type="mesh" contype="0" conaffinity="0" group="1" density="0" mesh="meca_500_r3_j5"/>
              <geom type="mesh" mesh="meca_500_r3_j5_collision"/>
              <body name="meca_axis_6_link" pos="0.07 0 0">
                <joint name="meca_axis_6_joint" pos="0 0 0" axis="1 0 0" range="-3.14159 3.14159" actuatorfrcrange="-10 10"/>
                <geom type="mesh" contype="0" conaffinity="0" group="1" density="0" mesh="meca_500_r3_j6"/>
                <geom type="mesh" mesh="meca_500_r3_j6_collision"/>
              </body>
            </body>
          </body>
        </body>
      </body>
    </body>
  </worldbody>
</mujoco>
